/home/yadunand/miniconda3/envs/parsl_py3.11/lib/python3.11/site-packages/pydantic/_internal/_config.py:322: UserWarning: Valid config keys have changed in V2:
* 'underscore_attrs_are_private' has been removed
  warnings.warn(message, UserWarning)
/home/yadunand/miniconda3/envs/parsl_py3.11/lib/python3.11/site-packages/pydantic/_internal/_config.py:322: UserWarning: Valid config keys have changed in V2:
* 'allow_population_by_field_name' has been renamed to 'populate_by_name'
  warnings.warn(message, UserWarning)
/home/yadunand/miniconda3/envs/parsl_py3.11/lib/python3.11/site-packages/pydantic/_internal/_config.py:322: UserWarning: Valid config keys have changed in V2:
* 'allow_population_by_field_name' has been renamed to 'populate_by_name'
* 'underscore_attrs_are_private' has been removed
  warnings.warn(message, UserWarning)
start:3981151.010476932
Selecting parsl_config: {'label': 'local-htex', 'max_workers_per_node': 2, 'provider': LocalProvider(
    channel=LocalChannel(
        envs={}, 
        script_dir=None, 
        userhome='/home/yadunand/flox-scaling-tests/parsl-tests'
    ), 
    cmd_timeout=30, 
    init_blocks=1, 
    launcher=SingleNodeLauncher(debug=True, fail_on_any=False), 
    max_blocks=1, 
    min_blocks=0, 
    move_files=None, 
    nodes_per_block=1, 
    parallelism=1, 
    worker_init='export PYTHONPATH=/home/yadunand/flox-scaling-tests/parsl-tests:$PYTHONPATH'
)}
dfk_start_done:3981166.529485101
priming_done:3981170.381309111
federated_fit::sync:   0%|          | 0/1 [00:00<?, ?it/s]Traceback (most recent call last):
  File "/home/yadunand/flox-scaling-tests/parsl-tests/test.py", line 136, in <module>
    main(parsed_args)
  File "/home/yadunand/flox-scaling-tests/parsl-tests/test.py", line 89, in main
    flox.federated_fit(
  File "/home/yadunand/miniconda3/envs/parsl_py3.11/lib/python3.11/site-packages/flox/runtime/fit.py", line 118, in federated_fit
    trained_module, history = process.start(debug_mode)
                              ^^^^^^^^^^^^^^^^^^^^^^^^^
  File "/home/yadunand/miniconda3/envs/parsl_py3.11/lib/python3.11/site-packages/flox/runtime/process/process_sync.py", line 80, in start
    step_result = self.step().result()
                  ^^^^^^^^^^^^^^^^^^^^
  File "/home/yadunand/miniconda3/envs/parsl_py3.11/lib/python3.11/concurrent/futures/_base.py", line 456, in result
    return self.__get_result()
           ^^^^^^^^^^^^^^^^^^^
  File "/home/yadunand/miniconda3/envs/parsl_py3.11/lib/python3.11/concurrent/futures/_base.py", line 401, in __get_result
    raise self._exception
  File "/home/yadunand/miniconda3/envs/parsl_py3.11/lib/python3.11/site-packages/parsl/executors/high_throughput/executor.py", line 520, in _queue_management_worker
    s.reraise()
  File "/home/yadunand/miniconda3/envs/parsl_py3.11/lib/python3.11/site-packages/parsl/app/errors.py", line 118, in reraise
    raise v
  File "/home/yadunand/miniconda3/envs/parsl_py3.11/bin/process_worker_pool.py", line 446, in worker_watchdog
    raise WorkerLost(worker_id, platform.node())

parsl.executors.high_throughput.errors.WorkerLost: Task failure due to loss of worker 0 on host exp-9-56
